Workbook

Sheet Start Here
A1: THE PRAEDIUM GROUP — Agent Score Card
A3: HOW THIS WORKS
A4: 1. | B4: You have two tabs with your name on them: your Weekly Scorecard and your one-time Assessment.
A5: 2. | B5: Complete your Assessment first (target: before our next meeting). Estimates are fine — there are no “right” answers. Your Q4 goals in Section 13 drive the progress tracker on your Scorecard.
A6: 3. | B6: Every week, fill in your row on your Scorecard by Friday end of day. It takes about 5 minutes.
A7: 4. | B7: You'll get an email reminder each Friday with a direct link to your tab. If last week is still blank on Monday, you'll get a gentle nudge.
A8: 5. | B8: Only yellow cells are for you. Gray/blue cells calculate automatically. You can only edit your own tabs.
A10: WHAT TO TRACK EACH WEEK
A11: Calls / Outreach | B11: Every dial, email, text, or door knock aimed at a prospect (owner, tenant, investor).
A12: DM Conversations | B12: Real conversations with a decision maker — not voicemails or gatekeepers.
A13: Meetings | B13: Discovery, listing, buyer/tenant, or prospect meetings held (in person or video).
A14: New Opportunities | B14: A qualified prospect with a real need, timeline, and next step.
A15: MC Conversations | B15: Meaningful conversations with agents in your KW Market Center about commercial.
A16: Sphere Touches | B16: Intentional contacts with attorneys, CPAs, lenders, developers, past clients, etc.
A17: Pipeline GCI | B17: Your best estimate of total potential GCI in your active pipeline at week's end.
A19: QUESTIONS? | B19: Reach out any time — this is a tool to help you grow, not a report card.

Sheet Dashboard
A1: Team Dashboard — Agent Score Card
A2: Owner view. Change the “Week of” date to look at any week (defaults to the current week). Everything on this tab is calculated — agents update their own Scorecard tabs.
A3: Week of: | B3: =TODAY()-WEEKDAY(TODAY(),3) | C3: ← type any Monday to review a past week
A5: Agent | B5: Assessment Done | C5: Week Status | D5: RE Hours | E5: Prospecting Hrs | F5: Calls / Outreach | G5: DM Conversations | H5: Meetings | I5: New Opps | J5: New DB Contacts | K5: Follow-Ups Open | L5: MC Convos | M5: Pipeline GCI (latest) | N5: Q4 GCI Closed | O5: Q4 GCI Goal | P5: Q4 GCI % | Q5: Q4 Closings | R5: Q4 Closing Goal | S5: Weekly Consistency | T5: Avg Calls / Wk | U5: Last Updated | V5: Win of the Week | W5: Biggest Obstacle
A6: =IF('Settings'!B14="","Agent 1",'Settings'!B14) | B6: ='Agent 1 Assessment'!C3 | C6: =IFERROR(INDEX('Agent 1 Scorecard'!$Z$15:$Z$80,MATCH($B$3,'Agent 1 Scorecard'!$A$15:$A$80,0)),"") | D6: =IFERROR(INDEX('Agent 1 Scorecard'!$C$15:$C$80,MATCH($B$3,'Agent 1 Scorecard'!$A$15:$A$80,0)),"") | E6: =IFERROR(INDEX('Agent 1 Scorecard'!$E$15:$E$80,MATCH($B$3,'Agent 1 Scorecard'!$A$15:$A$80,0)),"") | F6: =IFERROR(INDEX('Agent 1 Scorecard'!$F$15:$F$80,MATCH($B$3,'Agent 1 Scorecard'!$A$15:$A$80,0)),"") | G6: =IFERROR(INDEX('Agent 1 Scorecard'!$G$15:$G$80,MATCH($B$3,'Agent 1 Scorecard'!$A$15:$A$80,0)),"") | H6: =IFERROR(INDEX('Agent 1 Scorecard'!$H$15:$H$80,MATCH($B$3,'Agent 1 Scorecard'!$A$15:$A$80,0)),"") | I6: =IFERROR(INDEX('Agent 1 Scorecard'!$I$15:$I$80,MATCH($B$3,'Agent 1 Scorecard'!$A$15:$A$80,0)),"") | J6: =IFERROR(INDEX('Agent 1 Scorecard'!$J$15:$J$80,MATCH($B$3,'Agent 1 Scorecard'!$A$15:$A$80,0)),"") | K6: =IFERROR(INDEX('Agent 1 Scorecard'!$K$15:$K$80,MATCH($B$3,'Agent 1 Scorecard'!$A$15:$A$80,0)),"") | L6: =IFERROR(INDEX('Agent 1 Scorecard'!$L$15:$L$80,MATCH($B$3,'Agent 1 Scorecard'!$A$15:$A$80,0)),"") | M6: ='Agent 1 Scorecard'!K10 | N6: ='Agent 1 Scorecard'!D6 | O6: ='Agent 1 Scorecard'!C6 | P6: ='Agent 1 Scorecard'!E6 | Q6: ='Agent 1 Scorecard'!D8 | R6: ='Agent 1 Scorecard'!C8 | S6: ='Agent 1 Scorecard'!K7 | T6: ='Agent 1 Scorecard'!K8 | U6: =IF(MAX('Agent 1 Scorecard'!$Y$15:$Y$80)=0,"",MAX('Agent 1 Scorecard'!$Y$15:$Y$80)) | V6: =IFERROR(INDEX('Agent 1 Scorecard'!$V$15:$V$80,MATCH($B$3,'Agent 1 Scorecard'!$A$15:$A$80,0)),"") | W6: =IFERROR(INDEX('Agent 1 Scorecard'!$W$15:$W$80,MATCH($B$3,'Agent 1 Scorecard'!$A$15:$A$80,0)),"")
A7: =IF('Settings'!B15="","Agent 2",'Settings'!B15) | B7: ='Agent 2 Assessment'!C3 | C7: =IFERROR(INDEX('Agent 2 Scorecard'!$Z$15:$Z$80,MATCH($B$3,'Agent 2 Scorecard'!$A$15:$A$80,0)),"") | D7: =IFERROR(INDEX('Agent 2 Scorecard'!$C$15:$C$80,MATCH($B$3,'Agent 2 Scorecard'!$A$15:$A$80,0)),"") | E7: =IFERROR(INDEX('Agent 2 Scorecard'!$E$15:$E$80,MATCH($B$3,'Agent 2 Scorecard'!$A$15:$A$80,0)),"") | F7: =IFERROR(INDEX('Agent 2 Scorecard'!$F$15:$F$80,MATCH($B$3,'Agent 2 Scorecard'!$A$15:$A$80,0)),"") | G7: =IFERROR(INDEX('Agent 2 Scorecard'!$G$15:$G$80,MATCH($B$3,'Agent 2 Scorecard'!$A$15:$A$80,0)),"") | H7: =IFERROR(INDEX('Agent 2 Scorecard'!$H$15:$H$80,MATCH($B$3,'Agent 2 Scorecard'!$A$15:$A$80,0)),"") | I7: =IFERROR(INDEX('Agent 2 Scorecard'!$I$15:$I$80,MATCH($B$3,'Agent 2 Scorecard'!$A$15:$A$80,0)),"") | J7: =IFERROR(INDEX('Agent 2 Scorecard'!$J$15:$J$80,MATCH($B$3,'Agent 2 Scorecard'!$A$15:$A$80,0)),"") | K7: =IFERROR(INDEX('Agent 2 Scorecard'!$K$15:$K$80,MATCH($B$3,'Agent 2 Scorecard'!$A$15:$A$80,0)),"") | L7: =IFERROR(INDEX('Agent 2 Scorecard'!$L$15:$L$80,MATCH($B$3,'Agent 2 Scorecard'!$A$15:$A$80,0)),"") | M7: ='Agent 2 Scorecard'!K10 | N7: ='Agent 2 Scorecard'!D6 | O7: ='Agent 2 Scorecard'!C6 | P7: ='Agent 2 Scorecard'!E6 | Q7: ='Agent 2 Scorecard'!D8 | R7: ='Agent 2 Scorecard'!C8 | S7: ='Agent 2 Scorecard'!K7 | T7: ='Agent 2 Scorecard'!K8 | U7: =IF(MAX('Agent 2 Scorecard'!$Y$15:$Y$80)=0,"",MAX('Agent 2 Scorecard'!$Y$15:$Y$80)) | V7: =IFERROR(INDEX('Agent 2 Scorecard'!$V$15:$V$80,MATCH($B$3,'Agent 2 Scorecard'!$A$15:$A$80,0)),"") | W7: =IFERROR(INDEX('Agent 2 Scorecard'!$W$15:$W$80,MATCH($B$3,'Agent 2 Scorecard'!$A$15:$A$80,0)),"")
A8: =IF('Settings'!B16="","Agent 3",'Settings'!B16) | B8: ='Agent 3 Assessment'!C3 | C8: =IFERROR(INDEX('Agent 3 Scorecard'!$Z$15:$Z$80,MATCH($B$3,'Agent 3 Scorecard'!$A$15:$A$80,0)),"") | D8: =IFERROR(INDEX('Agent 3 Scorecard'!$C$15:$C$80,MATCH($B$3,'Agent 3 Scorecard'!$A$15:$A$80,0)),"") | E8: =IFERROR(INDEX('Agent 3 Scorecard'!$E$15:$E$80,MATCH($B$3,'Agent 3 Scorecard'!$A$15:$A$80,0)),"") | F8: =IFERROR(INDEX('Agent 3 Scorecard'!$F$15:$F$80,MATCH($B$3,'Agent 3 Scorecard'!$A$15:$A$80,0)),"") | G8: =IFERROR(INDEX('Agent 3 Scorecard'!$G$15:$G$80,MATCH($B$3,'Agent 3 Scorecard'!$A$15:$A$80,0)),"") | H8: =IFERROR(INDEX('Agent 3 Scorecard'!$H$15:$H$80,MATCH($B$3,'Agent 3 Scorecard'!$A$15:$A$80,0)),"") | I8: =IFERROR(INDEX('Agent 3 Scorecard'!$I$15:$I$80,MATCH($B$3,'Agent 3 Scorecard'!$A$15:$A$80,0)),"") | J8: =IFERROR(INDEX('Agent 3 Scorecard'!$J$15:$J$80,MATCH($B$3,'Agent 3 Scorecard'!$A$15:$A$80,0)),"") | K8: =IFERROR(INDEX('Agent 3 Scorecard'!$K$15:$K$80,MATCH($B$3,'Agent 3 Scorecard'!$A$15:$A$80,0)),"") | L8: =IFERROR(INDEX('Agent 3 Scorecard'!$L$15:$L$80,MATCH($B$3,'Agent 3 Scorecard'!$A$15:$A$80,0)),"") | M8: ='Agent 3 Scorecard'!K10 | N8: ='Agent 3 Scorecard'!D6 | O8: ='Agent 3 Scorecard'!C6 | P8: ='Agent 3 Scorecard'!E6 | Q8: ='Agent 3 Scorecard'!D8 | R8: ='Agent 3 Scorecard'!C8 | S8: ='Agent 3 Scorecard'!K7 | T8: ='Agent 3 Scorecard'!K8 | U8: =IF(MAX('Agent 3 Scorecard'!$Y$15:$Y$80)=0,"",MAX('Agent 3 Scorecard'!$Y$15:$Y$80)) | V8: =IFERROR(INDEX('Agent 3 Scorecard'!$V$15:$V$80,MATCH($B$3,'Agent 3 Scorecard'!$A$15:$A$80,0)),"") | W8: =IFERROR(INDEX('Agent 3 Scorecard'!$W$15:$W$80,MATCH($B$3,'Agent 3 Scorecard'!$A$15:$A$80,0)),"")
A9: =IF('Settings'!B17="","Agent 4",'Settings'!B17) | B9: ='Agent 4 Assessment'!C3 | C9: =IFERROR(INDEX('Agent 4 Scorecard'!$Z$15:$Z$80,MATCH($B$3,'Agent 4 Scorecard'!$A$15:$A$80,0)),"") | D9: =IFERROR(INDEX('Agent 4 Scorecard'!$C$15:$C$80,MATCH($B$3,'Agent 4 Scorecard'!$A$15:$A$80,0)),"") | E9: =IFERROR(INDEX('Agent 4 Scorecard'!$E$15:$E$80,MATCH($B$3,'Agent 4 Scorecard'!$A$15:$A$80,0)),"") | F9: =IFERROR(INDEX('Agent 4 Scorecard'!$F$15:$F$80,MATCH($B$3,'Agent 4 Scorecard'!$A$15:$A$80,0)),"") | G9: =IFERROR(INDEX('Agent 4 Scorecard'!$G$15:$G$80,MATCH($B$3,'Agent 4 Scorecard'!$A$15:$A$80,0)),"") | H9: =IFERROR(INDEX('Agent 4 Scorecard'!$H$15:$H$80,MATCH($B$3,'Agent 4 Scorecard'!$A$15:$A$80,0)),"") | I9: =IFERROR(INDEX('Agent 4 Scorecard'!$I$15:$I$80,MATCH($B$3,'Agent 4 Scorecard'!$A$15:$A$80,0)),"") | J9: =IFERROR(INDEX('Agent 4 Scorecard'!$J$15:$J$80,MATCH($B$3,'Agent 4 Scorecard'!$A$15:$A$80,0)),"") | K9: =IFERROR(INDEX('Agent 4 Scorecard'!$K$15:$K$80,MATCH($B$3,'Agent 4 Scorecard'!$A$15:$A$80,0)),"") | L9: =IFERROR(INDEX('Agent 4 Scorecard'!$L$15:$L$80,MATCH($B$3,'Agent 4 Scorecard'!$A$15:$A$80,0)),"") | M9: ='Agent 4 Scorecard'!K10 | N9: ='Agent 4 Scorecard'!D6 | O9: ='Agent 4 Scorecard'!C6 | P9: ='Agent 4 Scorecard'!E6 | Q9: ='Agent 4 Scorecard'!D8 | R9: ='Agent 4 Scorecard'!C8 | S9: ='Agent 4 Scorecard'!K7 | T9: ='Agent 4 Scorecard'!K8 | U9: =IF(MAX('Agent 4 Scorecard'!$Y$15:$Y$80)=0,"",MAX('Agent 4 Scorecard'!$Y$15:$Y$80)) | V9: =IFERROR(INDEX('Agent 4 Scorecard'!$V$15:$V$80,MATCH($B$3,'Agent 4 Scorecard'!$A$15:$A$80,0)),"") | W9: =IFERROR(INDEX('Agent 4 Scorecard'!$W$15:$W$80,MATCH($B$3,'Agent 4 Scorecard'!$A$15:$A$80,0)),"")
A10: =IF('Settings'!B18="","Agent 5",'Settings'!B18) | B10: ='Agent 5 Assessment'!C3 | C10: =IFERROR(INDEX('Agent 5 Scorecard'!$Z$15:$Z$80,MATCH($B$3,'Agent 5 Scorecard'!$A$15:$A$80,0)),"") | D10: =IFERROR(INDEX('Agent 5 Scorecard'!$C$15:$C$80,MATCH($B$3,'Agent 5 Scorecard'!$A$15:$A$80,0)),"") | E10: =IFERROR(INDEX('Agent 5 Scorecard'!$E$15:$E$80,MATCH($B$3,'Agent 5 Scorecard'!$A$15:$A$80,0)),"") | F10: =IFERROR(INDEX('Agent 5 Scorecard'!$F$15:$F$80,MATCH($B$3,'Agent 5 Scorecard'!$A$15:$A$80,0)),"") | G10: =IFERROR(INDEX('Agent 5 Scorecard'!$G$15:$G$80,MATCH($B$3,'Agent 5 Scorecard'!$A$15:$A$80,0)),"") | H10: =IFERROR(INDEX('Agent 5 Scorecard'!$H$15:$H$80,MATCH($B$3,'Agent 5 Scorecard'!$A$15:$A$80,0)),"") | I10: =IFERROR(INDEX('Agent 5 Scorecard'!$I$15:$I$80,MATCH($B$3,'Agent 5 Scorecard'!$A$15:$A$80,0)),"") | J10: =IFERROR(INDEX('Agent 5 Scorecard'!$J$15:$J$80,MATCH($B$3,'Agent 5 Scorecard'!$A$15:$A$80,0)),"") | K10: =IFERROR(INDEX('Agent 5 Scorecard'!$K$15:$K$80,MATCH($B$3,'Agent 5 Scorecard'!$A$15:$A$80,0)),"") | L10: =IFERROR(INDEX('Agent 5 Scorecard'!$L$15:$L$80,MATCH($B$3,'Agent 5 Scorecard'!$A$15:$A$80,0)),"") | M10: ='Agent 5 Scorecard'!K10 | N10: ='Agent 5 Scorecard'!D6 | O10: ='Agent 5 Scorecard'!C6 | P10: ='Agent 5 Scorecard'!E6 | Q10: ='Agent 5 Scorecard'!D8 | R10: ='Agent 5 Scorecard'!C8 | S10: ='Agent 5 Scorecard'!K7 | T10: ='Agent 5 Scorecard'!K8 | U10: =IF(MAX('Agent 5 Scorecard'!$Y$15:$Y$80)=0,"",MAX('Agent 5 Scorecard'!$Y$15:$Y$80)) | V10: =IFERROR(INDEX('Agent 5 Scorecard'!$V$15:$V$80,MATCH($B$3,'Agent 5 Scorecard'!$A$15:$A$80,0)),"") | W10: =IFERROR(INDEX('Agent 5 Scorecard'!$W$15:$W$80,MATCH($B$3,'Agent 5 Scorecard'!$A$15:$A$80,0)),"")
A11: =IF('Settings'!B19="","Agent 6",'Settings'!B19) | B11: ='Agent 6 Assessment'!C3 | C11: =IFERROR(INDEX('Agent 6 Scorecard'!$Z$15:$Z$80,MATCH($B$3,'Agent 6 Scorecard'!$A$15:$A$80,0)),"") | D11: =IFERROR(INDEX('Agent 6 Scorecard'!$C$15:$C$80,MATCH($B$3,'Agent 6 Scorecard'!$A$15:$A$80,0)),"") | E11: =IFERROR(INDEX('Agent 6 Scorecard'!$E$15:$E$80,MATCH($B$3,'Agent 6 Scorecard'!$A$15:$A$80,0)),"") | F11: =IFERROR(INDEX('Agent 6 Scorecard'!$F$15:$F$80,MATCH($B$3,'Agent 6 Scorecard'!$A$15:$A$80,0)),"") | G11: =IFERROR(INDEX('Agent 6 Scorecard'!$G$15:$G$80,MATCH($B$3,'Agent 6 Scorecard'!$A$15:$A$80,0)),"") | H11: =IFERROR(INDEX('Agent 6 Scorecard'!$H$15:$H$80,MATCH($B$3,'Agent 6 Scorecard'!$A$15:$A$80,0)),"") | I11: =IFERROR(INDEX('Agent 6 Scorecard'!$I$15:$I$80,MATCH($B$3,'Agent 6 Scorecard'!$A$15:$A$80,0)),"") | J11: =IFERROR(INDEX('Agent 6 Scorecard'!$J$15:$J$80,MATCH($B$3,'Agent 6 Scorecard'!$A$15:$A$80,0)),"") | K11: =IFERROR(INDEX('Agent 6 Scorecard'!$K$15:$K$80,MATCH($B$3,'Agent 6 Scorecard'!$A$15:$A$80,0)),"") | L11: =IFERROR(INDEX('Agent 6 Scorecard'!$L$15:$L$80,MATCH($B$3,'Agent 6 Scorecard'!$A$15:$A$80,0)),"") | M11: ='Agent 6 Scorecard'!K10 | N11: ='Agent 6 Scorecard'!D6 | O11: ='Agent 6 Scorecard'!C6 | P11: ='Agent 6 Scorecard'!E6 | Q11: ='Agent 6 Scorecard'!D8 | R11: ='Agent 6 Scorecard'!C8 | S11: ='Agent 6 Scorecard'!K7 | T11: ='Agent 6 Scorecard'!K8 | U11: =IF(MAX('Agent 6 Scorecard'!$Y$15:$Y$80)=0,"",MAX('Agent 6 Scorecard'!$Y$15:$Y$80)) | V11: =IFERROR(INDEX('Agent 6 Scorecard'!$V$15:$V$80,MATCH($B$3,'Agent 6 Scorecard'!$A$15:$A$80,0)),"") | W11: =IFERROR(INDEX('Agent 6 Scorecard'!$W$15:$W$80,MATCH($B$3,'Agent 6 Scorecard'!$A$15:$A$80,0)),"")
A12: =IF('Settings'!B20="","Agent 7",'Settings'!B20) | B12: ='Agent 7 Assessment'!C3 | C12: =IFERROR(INDEX('Agent 7 Scorecard'!$Z$15:$Z$80,MATCH($B$3,'Agent 7 Scorecard'!$A$15:$A$80,0)),"") | D12: =IFERROR(INDEX('Agent 7 Scorecard'!$C$15:$C$80,MATCH($B$3,'Agent 7 Scorecard'!$A$15:$A$80,0)),"") | E12: =IFERROR(INDEX('Agent 7 Scorecard'!$E$15:$E$80,MATCH($B$3,'Agent 7 Scorecard'!$A$15:$A$80,0)),"") | F12: =IFERROR(INDEX('Agent 7 Scorecard'!$F$15:$F$80,MATCH($B$3,'Agent 7 Scorecard'!$A$15:$A$80,0)),"") | G12: =IFERROR(INDEX('Agent 7 Scorecard'!$G$15:$G$80,MATCH($B$3,'Agent 7 Scorecard'!$A$15:$A$80,0)),"") | H12: =IFERROR(INDEX('Agent 7 Scorecard'!$H$15:$H$80,MATCH($B$3,'Agent 7 Scorecard'!$A$15:$A$80,0)),"") | I12: =IFERROR(INDEX('Agent 7 Scorecard'!$I$15:$I$80,MATCH($B$3,'Agent 7 Scorecard'!$A$15:$A$80,0)),"") | J12: =IFERROR(INDEX('Agent 7 Scorecard'!$J$15:$J$80,MATCH($B$3,'Agent 7 Scorecard'!$A$15:$A$80,0)),"") | K12: =IFERROR(INDEX('Agent 7 Scorecard'!$K$15:$K$80,MATCH($B$3,'Agent 7 Scorecard'!$A$15:$A$80,0)),"") | L12: =IFERROR(INDEX('Agent 7 Scorecard'!$L$15:$L$80,MATCH($B$3,'Agent 7 Scorecard'!$A$15:$A$80,0)),"") | M12: ='Agent 7 Scorecard'!K10 | N12: ='Agent 7 Scorecard'!D6 | O12: ='Agent 7 Scorecard'!C6 | P12: ='Agent 7 Scorecard'!E6 | Q12: ='Agent 7 Scorecard'!D8 | R12: ='Agent 7 Scorecard'!C8 | S12: ='Agent 7 Scorecard'!K7 | T12: ='Agent 7 Scorecard'!K8 | U12: =IF(MAX('Agent 7 Scorecard'!$Y$15:$Y$80)=0,"",MAX('Agent 7 Scorecard'!$Y$15:$Y$80)) | V12: =IFERROR(INDEX('Agent 7 Scorecard'!$V$15:$V$80,MATCH($B$3,'Agent 7 Scorecard'!$A$15:$A$80,0)),"") | W12: =IFERROR(INDEX('Agent 7 Scorecard'!$W$15:$W$80,MATCH($B$3,'Agent 7 Scorecard'!$A$15:$A$80,0)),"")
A13: TEAM TOTAL | D13: =SUM(D6:D12) | E13: =SUM(E6:E12) | F13: =SUM(F6:F12) | G13: =SUM(G6:G12) | H13: =SUM(H6:H12) | I13: =SUM(I6:I12) | J13: =SUM(J6:J12) | K13: =SUM(K6:K12) | ... O13: =SUM(O6:O12) | Q13: =SUM(Q6:Q12) | R13: =SUM(R6:R12)

Sheet Settings
A1: Settings — Score Card Automation
A2: Owner-only. Fill in agent names + emails, then use the Score Card menu → “Rename tabs from Settings” and “Share & protect”. Email schedule changes take effect after “Install weekly email triggers”.
A4: Owner name | C4: Nicholas Carnes
A5: Owner email (weekly team summary goes here) | C5: nicholascarnes45@gmail.com
A6: Team name | C6: The Praedium Group
A7: Agent reminder day | C7: FRIDAY
A8: Agent reminder hour (0–23) | C8: 9
A9: Owner summary day | C9: MONDAY
A10: Owner summary hour (0–23) | C10: 7
A11: Send Monday nudge to agents who missed last week? | C11: Yes
A13: # | B13: Agent Name | C13: Agent Email | D13: Scorecard Tab | E13: Assessment Tab | F13: Market Center
A14: 1 | D14: Agent 1 Scorecard | E14: Agent 1 Assessment
A15: 2 | D15: Agent 2 Scorecard | E15: Agent 2 Assessment
A16: 3 | D16: Agent 3 Scorecard | E16: Agent 3 Assessment
A17: 4 | D17: Agent 4 Scorecard | E17: Agent 4 Assessment
A18: 5 | D18: Agent 5 Scorecard | E18: Agent 5 Assessment
A19: 6 | D19: Agent 6 Scorecard | E19: Agent 6 Assessment
A20: 7 | D20: Agent 7 Scorecard | E20: Agent 7 Assessment
A22: Scorecard/Assessment Tab columns are maintained by the script — don't edit them by hand.

Sheet Agent 1 Scorecard
A1: =IF('Settings'!B14="","Agent 1",'Settings'!B14)&" — Weekly Score Card"
A2: Fill in your row for the current week by Friday end of day (yellow cells). Estimates are fine. “Follow-Ups Outstanding” and “Pipeline Potential GCI” are snapshots as of the end of the week; everything else is what happened that week. Q4 progress below updates automatically.
A4: Q4 2026 PROGRESS (goals come from Section 13 of your Assessment) | H4: ACCOUNTABILITY
A5: Metric | C5: Q4 Goal | D5: Q4 Actual | E5: % to Goal | F5: On Pace? | H5: Weeks updated | K5: =COUNTIFS($A$15:$A$80,"<="&TODAY(),$Y$15:$Y$80,"<>")
A6: Commercial GCI | C6: =IF('Agent 1 Assessment'!C285="","",'Agent 1 Assessment'!C285) | D6: =SUMIFS($T$15:$T$80,$A$15:$A$80,">="&DATE(2026,9,28),$A$15:$A$80,"<="&DATE(2026,12,31)) | E6: =IFERROR(D6/C6,"") | F6: =IF(C6="","Set goal",IF(D6>=C6*MAX(0,MIN(1,(TODAY()-DATE(2026,10,1))/(DATE(2026,12,31)-DATE(2026,10,1)))),"On pace","Behind")) | H6: Weeks elapsed | K6: =COUNTIFS($A$15:$A$80,"<="&TODAY())
A7: Transaction Volume | C7: =IF('Agent 1 Assessment'!C284="","",'Agent 1 Assessment'!C284) | D7: =SUMIFS($S$15:$S$80,$A$15:$A$80,">="&DATE(2026,9,28),$A$15:$A$80,"<="&DATE(2026,12,31)) | E7: =IFERROR(D7/C7,"") | F7: =IF(C7="","Set goal",IF(D7>=C7*MAX(0,MIN(1,(TODAY()-DATE(2026,10,1))/(DATE(2026,12,31)-DATE(2026,10,1)))),"On pace","Behind")) | H7: Consistency | K7: =IFERROR(K5/K6,0)
A8: Closings | C8: =IF('Agent 1 Assessment'!C286="","",'Agent 1 Assessment'!C286) | D8: =SUMIFS($R$15:$R$80,$A$15:$A$80,">="&DATE(2026,9,28),$A$15:$A$80,"<="&DATE(2026,12,31)) | E8: =IFERROR(D8/C8,"") | F8: =IF(C8="","Set goal",IF(D8>=C8*MAX(0,MIN(1,(TODAY()-DATE(2026,10,1))/(DATE(2026,12,31)-DATE(2026,10,1)))),"On pace","Behind")) | H8: Avg calls / week | K8: =IFERROR(AVERAGEIFS($F$15:$F$80,$A$15:$A$80,"<="&TODAY(),$F$15:$F$80,"<>"),0)
A9: New Listings | C9: =IF('Agent 1 Assessment'!C287="","",'Agent 1 Assessment'!C287) | D9: =SUMIFS($N$15:$N$80,$A$15:$A$80,">="&DATE(2026,9,28),$A$15:$A$80,"<="&DATE(2026,12,31)) | E9: =IFERROR(D9/C9,"") | F9: =IF(C9="","Set goal",IF(D9>=C9*MAX(0,MIN(1,(TODAY()-DATE(2026,10,1))/(DATE(2026,12,31)-DATE(2026,10,1)))),"On pace","Behind")) | H9: Avg meetings / week | K9: =IFERROR(AVERAGEIFS($H$15:$H$80,$A$15:$A$80,"<="&TODAY(),$H$15:$H$80,"<>"),0)
A10: New Buyer / Tenant Assignments | C10: =IF('Agent 1 Assessment'!C288="","",'Agent 1 Assessment'!C288) | D10: =SUMIFS($O$15:$O$80,$A$15:$A$80,">="&DATE(2026,9,28),$A$15:$A$80,"<="&DATE(2026,12,31)) | E10: =IFERROR(D10/C10,"") | F10: =IF(C10="","Set goal",IF(D10>=C10*MAX(0,MIN(1,(TODAY()-DATE(2026,10,1))/(DATE(2026,12,31)-DATE(2026,10,1)))),"On pace","Behind")) | H10: Latest pipeline GCI | K10: =IFERROR(INDEX($U$15:$U$80,MATCH(1E+100,$U$15:$U$80)),"")
A11: Qualified Opportunities Created | C11: =IF('Agent 1 Assessment'!C289="","",'Agent 1 Assessment'!C289) | D11: =SUMIFS($I$15:$I$80,$A$15:$A$80,">="&DATE(2026,9,28),$A$15:$A$80,"<="&DATE(2026,12,31)) | E11: =IFERROR(D11/C11,"") | F11: =IF(C11="","Set goal",IF(D11>=C11*MAX(0,MIN(1,(TODAY()-DATE(2026,10,1))/(DATE(2026,12,31)-DATE(2026,10,1)))),"On pace","Behind")) | H11: Assessment complete | K11: ='Agent 1 Assessment'!C3
A12: Meetings (goal = per month × 3) | C12: =IF('Agent 1 Assessment'!C290="","",'Agent 1 Assessment'!C290*3) | D12: =SUMIFS($H$15:$H$80,$A$15:$A$80,">="&DATE(2026,9,28),$A$15:$A$80,"<="&DATE(2026,12,31)) | E12: =IFERROR(D12/C12,"") | F12: =IF(C12="","Set goal",IF(D12>=C12*MAX(0,MIN(1,(TODAY()-DATE(2026,10,1))/(DATE(2026,12,31)-DATE(2026,10,1)))),"On pace","Behind"))
A14: Week Of (Mon) | B14: Days Worked | C14: Total RE Hours | D14: Commercial Hours | E14: Prospecting Hours | F14: Calls / Outreach Attempts | G14: Decision-Maker Conversations | H14: Prospect / Client Meetings | I14: New Opportunities Created | J14: New Database Contacts | K14: Follow-Ups Outstanding | L14: Market Center Agent Conversations | M14: Sphere Touches | N14: New Listings | O14: New Buyer / Tenant Assignments | P14: LOIs Submitted | Q14: Went Under Contract | R14: Closings | S14: Volume Closed ($) | T14: GCI Closed ($) | U14: Pipeline Potential GCI ($) | V14: Win of the Week | W14: Biggest Obstacle | X14: #1 Focus Next Week | Y14: Last Updated (auto) | Z14: Status
A15: 46293 | Z15: =IF(A15>TODAY(),"Upcoming",IF(Y15<>"","✓ Updated",IF(A15+6>=TODAY(),"Due Friday","⚠ Missing")))
A16: 46300 | Z16: =IF(A16>TODAY(),"Upcoming",IF(Y16<>"","✓ Updated",IF(A16+6>=TODAY(),"Due Friday","⚠ Missing")))
A17: 46307 | Z17: =IF(A17>TODAY(),"Upcoming",IF(Y17<>"","✓ Updated",IF(A17+6>=TODAY(),"Due Friday","⚠ Missing")))
A18: 46314 | Z18: =IF(A18>TODAY(),"Upcoming",IF(Y18<>"","✓ Updated",IF(A18+6>=TODAY(),"Due Friday","⚠ Missing")))
A19: 46321 | Z19: =IF(A19>TODAY(),"Upcoming",IF(Y19<>"","✓ Updated",IF(A19+6>=TODAY(),"Due Friday","⚠ Missing")))
A20: 46328 | Z20: =IF(A20>TODAY(),"Upcoming",IF(Y20<>"","✓ Updated",IF(A20+6>=TODAY(),"Due Friday","⚠ Missing")))
A21: 46335 | Z21: =IF(A21>TODAY(),"Upcoming",IF(Y21<>"","✓ Updated",IF(A21+6>=TODAY(),"Due Friday","⚠ Missing")))
A22: 46342 | Z22: =IF(A22>TODAY(),"Upcoming",IF(Y22<>"","✓ Updated",IF(A22+6>=TODAY(),"Due Friday","⚠ Missing")))
A23: 46349 | Z23: =IF(A23>TODAY(),"Upcoming",IF(Y23<>"","✓ Updated",IF(A23+6>=TODAY(),"Due Friday","⚠ Missing")))
A24: 46356 | Z24: =IF(A24>TODAY(),"Upcoming",IF(Y24<>"","✓ Updated",IF(A24+6>=TODAY(),"Due Friday","⚠ Missing")))
A25: 46363 | Z25: =IF(A25>TODAY(),"Upcoming",IF(Y25<>"","✓ Updated",IF(A25+6>=TODAY(),"Due Friday","⚠ Missing")))
A26: 46370 | Z26: =IF(A26>TODAY(),"Upcoming",IF(Y26<>"","✓ Updated",IF(A26+6>=TODAY(),"Due Friday","⚠ Missing")))
... A80: 46748 | Z80: =IF(A80>TODAY(),"Upcoming",IF(Y80<>"","✓ Updated",IF(A80+6>=TODAY(),"Due Friday","⚠ Missing")))

Sheet Agent 1 Assessment
A1: =IF('Settings'!B14="","Agent 1",'Settings'!B14)&" — Business Development & Growth Assessment"
A2: THE PRAEDIUM GROUP • This assessment helps us understand where you are today, where your time is going, and what training, structure, or support could help you grow. There are no “right” answers — answer based on what your business actually looks like today. Estimates are completely acceptable. Yellow cells are yours to fill in.
B3: Completion: | C3: =IFERROR(SUMPRODUCT((F5:F400=1)*(C5:C400<>""))/SUM(F5:F400),0)
A5: 1. ABOUT YOUR BUSINESS TODAY
B6: Market Center / KW Office | F6: 1
B7: How long have you been licensed in real estate? | F7: 1
B8: How long have you actively worked in commercial real estate? | F8: 1
B9: How would you describe your current real estate business? | F9: 1
B10: If you selected Other, please explain: | F10: 1
B11: Is real estate currently your primary occupation? | F11: 1
B12: If not, what other work or major commitments currently compete for your time? | F12: 1
A14: 2. YOUR CURRENT WORK WEEK
A15: We want to understand what your schedule actually looks like today.
B16: On average, how many days per week do you currently spend working on real estate? | F16: 1
B17: How many hours do you work on real estate during a typical day? | F17: 1
B18: What time do you normally begin your workday? | F18: 1
B19: What time do you normally finish your workday? | F19: 1
B20: Is your schedule generally consistent from day to day? | F20: 1
B22: Day | C22: Usually Work? | D22: Approx. Hours
B23: Monday | F23: 1
B24: Tuesday | F24: 1
B25: Wednesday | F25: 1
B26: Thursday | F26: 1
B27: Friday | F27: 1
B28: Saturday | F28: 1
B29: Sunday | F29: 1
B31: How is your typical real estate week divided?
B32: Area | C32: Hours / Week
B33: Commercial Real Estate | F33: 1
B34: Residential Real Estate | F34: 1
B35: Administrative / Business Operations | F35: 1
B36: Other | F36: 1
B37: TOTAL | C37: =SUM(C33:C36)
B38: If Other, what does that time consist of? | F38: 1
A40: 3. WHERE DOES YOUR TIME ACTUALLY GO?
A41: You do not need to track every minute. Think about a typical week and make your best estimate. Use this guide if you are unsure how to categorize something.
B42: Category | C42: Examples
B43: Prospecting / Business Development | C43: Cold calling, owner outreach, tenant outreach, email campaigns, canvassing, prospect research
B44: Client / Deal Work | C44: Tours, client meetings, LOIs, contracts, negotiations, due diligence, inspections, closing coordination
B45: Market Research | C45: Crexi, CoStar, GIS, Land id, researching ownership, comps, zoning, demographics
...

Sheet Agent 2 Scorecard
A1: =IF('Settings'!B15="","Agent 2",'Settings'!B15)&" — Weekly Score Card"
A2: Fill in your row for the current week by Friday end of day (yellow cells). Estimates are fine. “Follow-Ups Outstanding” and “Pipeline Potential GCI” are snapshots as of the end of the week; everything else is what happened that week. Q4 progress below updates automatically.
A4: Q4 2026 PROGRESS (goals come from Section 13 of your Assessment) | H4: ACCOUNTABILITY
A5: Metric | C5: Q4 Goal | D5: Q4 Actual | E5: % to Goal | F5: On Pace? | H5: Weeks updated | K5: =COUNTIFS($A$15:$A$80,"<="&TODAY(),$Y$15:$Y$80,"<>")
A6: Commercial GCI | C6: =IF('Agent 2 Assessment'!C285="","",'Agent 2 Assessment'!C285) | D6: =SUMIFS($T$15:$T$80,$A$15:$A$80,">="&DATE(2026,9,28),$A$15:$A$80,"<="&DATE(2026,12,31)) | E6: =IFERROR(D6/C6,"") | F6: =IF(C6="","Set goal",IF(D6>=C6*MAX(0,MIN(1,(TODAY()-DATE(2026,10,1))/(DATE(2026,12,31)-DATE(2026,10,1)))),"On pace","Behind")) | H6: Weeks elapsed | K6: =COUNTIFS($A$15:$A$80,"<="&TODAY())
A7: Transaction Volume | C7: =IF('Agent 2 Assessment'!C284="","",'Agent 2 Assessment'!C284) | D7: =SUMIFS($S$15:$S$80,$A$15:$A$80,">="&DATE(2026,9,28),$A$15:$A$80,"<="&DATE(2026,12,31)) | E7: =IFERROR(D7/C7,"") | F7: =IF(C7="","Set goal",IF(D7>=C7*MAX(0,MIN(1,(TODAY()-DATE(2026,10,1))/(DATE(2026,12,31)-DATE(2026,10,1)))),"On pace","Behind")) | H7: Consistency | K7: =IFERROR(K5/K6,0)
A8: Closings | C8: =IF('Agent 2 Assessment'!C286="","",'Agent 2 Assessment'!C286) | D8: =SUMIFS($R$15:$R$80,$A$15:$A$80,">="&DATE(2026,9,28),$A$15:$A$80,"<="&DATE(2026,12,31)) | E8: =IFERROR(D8/C8,"") | F8: =IF(C8="","Set goal",IF(D8>=C8*MAX(0,MIN(1,(TODAY()-DATE(2026,10,1))/(DATE(2026,12,31)-DATE(2026,10,1)))),"On pace","Behind")) | H8: Avg calls / week | K8: =IFERROR(AVERAGEIFS($F$15:$F$80,$A$15:$A$80,"<="&TODAY(),$F$15:$F$80,"<>"),0)
A9: New Listings | C9: =IF('Agent 2 Assessment'!C287="","",'Agent 2 Assessment'!C287) | D9: =SUMIFS($N$15:$N$80,$A$15:$A$80,">="&DATE(2026,9,28),$A$15:$A$80,"<="&DATE(2026,12,31)) | E9: =IFERROR(D9/C9,"") | F9: =IF(C9="","Set goal",IF(D9>=C9*MAX(0,MIN(1,(TODAY()-DATE(2026,10,1))/(DATE(2026,12,31)-DATE(2026,10,1)))),"On pace","Behind")) | H9: Avg meetings / week | K9: =IFERROR(AVERAGEIFS($H$15:$H$80,$A$15:$A$80,"<="&TODAY(),$H$15:$H$80,"<>"),0)
A10: New Buyer / Tenant Assignments | C10: =IF('Agent 2 Assessment'!C288="","",'Agent 2 Assessment'!C288) | D10: =SUMIFS($O$15:$O$80,$A$15:$A$80,">="&DATE(2026,9,28),$A$15:$A$80,"<="&DATE(2026,12,31)) | E10: =IFERROR(D10/C10,"") | F10: =IF(C10="","Set goal",IF(D10>=C10*MAX(0,MIN(1,(TODAY()-DATE(2026,10,1))/(DATE(2026,12,31)-DATE(2026,10,1)))),"On pace","Behind")) | H10: Latest pipeline GCI | K10: =IFERROR(INDEX($U$15:$U$80,MATCH(1E+100,$U$15:$U$80)),"")
A11: Qualified Opportunities Created | C11: =IF('Agent 2 Assessment'!C289="","",'Agent 2 Assessment'!C289) | D11: =SUMIFS($I$15:$I$80,$A$15:$A$80,">="&DATE(2026,9,28),$A$15:$A$80,"<="&DATE(2026,12,31)) | E11: =IFERROR(D11/C11,"") | F11: =IF(C11="","Set goal",IF(D11>=C11*MAX(0,MIN(1,(TODAY()-DATE(2026,10,1))/(DATE(2026,12,31)-DATE(2026,10,1)))),"On pace","Behind")) | H11: Assessment complete | K11: ='Agent 2 Assessment'!C3
A12: Meetings (goal = per month × 3) | C12: =IF('Agent 2 Assessment'!C290="","",'Agent 2 Assessment'!C290*3) | D12: =SUMIFS($H$15:$H$80,$A$15:$A$80,">="&DATE(2026,9,28),$A$15:$A$80,"<="&DATE(2026,12,31)) | E12: =IFERROR(D12/C12,"") | F12: =IF(C12="","Set goal",IF(D12>=C12*MAX(0,MIN(1,(TODAY()-DATE(2026,10,1))/(DATE(2026,12,31)-DATE(2026,10,1)))),"On pace","Behind"))
A14: Week Of (Mon) | B14: Days Worked | C14: Total RE Hours | D14: Commercial Hours | E14: Prospecting Hours | F14: Calls / Outreach Attempts | G14: Decision-Maker Conversations | H14: Prospect / Client Meetings | I14: New Opportunities Created | J14: New Database Contacts | K14: Follow-Ups Outstanding | L14: Market Center Agent Conversations | M14: Sphere Touches | N14: New Listings | O14: New Buyer / Tenant Assignments | P14: LOIs Submitted | Q14: Went Under Contract | R14: Closings | S14: Volume Closed ($) | T14: GCI Closed ($) | U14: Pipeline Potential GCI ($) | V14: Win of the Week | W14: Biggest Obstacle | X14: #1 Focus Next Week | Y14: Last Updated (auto) | Z14: Status
A15: 46293 | Z15: =IF(A15>TODAY(),"Upcoming",IF(Y15<>"","✓ Updated",IF(A15+6>=TODAY(),"Due Friday","⚠ Missing")))
A16: 46300 | Z16: =IF(A16>TODAY(),"Upcoming",IF(Y16<>"","✓ Updated",IF(A16+6>=TODAY(),"Due Friday","⚠ Missing")))
A17: 46307 | Z17: =IF(A17>TODAY(),"Upcoming",IF(Y17<>"","✓ Updated",IF(A17+6>=TODAY(),"Due Friday","⚠ Missing")))
A18: 46314 | Z18: =IF(A18>TODAY(),"Upcoming",IF(Y18<>"","✓ Updated",IF(A18+6>=TODAY(),"Due Friday","⚠ Missing")))
A19: 46321 | Z19: =IF(A19>TODAY(),"Upcoming",IF(Y19<>"","✓ Updated",IF(A19+6>=TODAY(),"Due Friday","⚠ Missing")))
A20: 46328 | Z20: =IF(A20>TODAY(),"Upcoming",IF(Y20<>"","✓ Updated",IF(A20+6>=TODAY(),"Due Friday","⚠ Missing")))
A21: 46335 | Z21: =IF(A21>TODAY(),"Upcoming",IF(Y21<>"","✓ Updated",IF(A21+6>=TODAY(),"Due Friday","⚠ Missing")))
A22: 46342 | Z22: =IF(A22>TODAY(),"Upcoming",IF(Y22<>"","✓ Updated",IF(A22+6>=TODAY(),"Due Friday","⚠ Missing")))
A23: 46349 | Z23: =IF(A23>TODAY(),"Upcoming",IF(Y23<>"","✓ Updated",IF(A23+6>=TODAY(),"Due Friday","⚠ Missing")))
A24: 46356 | Z24: =IF(A24>TODAY(),"Upcoming",IF(Y24<>"","✓ Updated",IF(A24+6>=TODAY(),"Due Friday","⚠ Missing")))
A25: 46363 | Z25: =IF(A25>TODAY(),"Upcoming",IF(Y25<>"","✓ Updated",IF(A25+6>=TODAY(),"Due Friday","⚠ Missing")))
A26: 46370 | Z26: =IF(A26>TODAY(),"Upcoming",IF(Y26<>"","✓ Updated",IF(A26+6>=TODAY(),"Due Friday","⚠ Missing")))
... A80: 46748 | Z80: =IF(A80>TODAY(),"Upcoming",IF(Y80<>"","✓ Updated",IF(A80+6>=TODAY(),"Due Friday","⚠ Missing")))

Sheet Agent 2 Assessment
A1: =IF('Settings'!B15="","Agent 2",'Settings'!B15)&" — Business Development & Growth Assessment"
A2: THE PRAEDIUM GROUP • This assessment helps us understand where you are today, where your time is going, and what training, structure, or support could help you grow. There are no “right” answers — answer based on what your business actually looks like today. Estimates are completely acceptable. Yellow cells are yours to fill in.
B3: Completion: | C3: =IFERROR(SUMPRODUCT((F5:F400=1)*(C5:C400<>""))/SUM(F5:F400),0)
A5: 1. ABOUT YOUR BUSINESS TODAY
B6: Market Center / KW Office | F6: 1
B7: How long have you been licensed in real estate? | F7: 1
B8: How long have you actively worked in commercial real estate? | F8: 1
B9: How would you describe your current real estate business? | F9: 1
B10: If you selected Other, please explain: | F10: 1
B11: Is real estate currently your primary occupation? | F11: 1
B12: If not, what other work or major commitments currently compete for your time? | F12: 1
A14: 2. YOUR CURRENT WORK WEEK
A15: We want to understand what your schedule actually looks like today.
B16: On average, how many days per week do you currently spend working on real estate? | F16: 1
B17: How many hours do you work on real estate during a typical day? | F17: 1
B18: What time do you normally begin your workday? | F18: 1
B19: What time do you normally finish your workday? | F19: 1
B20: Is your schedule generally consistent from day to day? | F20: 1
B22: Day | C22: Usually Work? | D22: Approx. Hours
B23: Monday | F23: 1
B24: Tuesday | F24: 1
B25: Wednesday | F25: 1
B26: Thursday | F26: 1
B27: Friday | F27: 1
B28: Saturday | F28: 1
B29: Sunday | F29: 1
B31: How is your typical real estate week divided?
B32: Area | C32: Hours / Week
B33: Commercial Real Estate | F33: 1
B34: Residential Real Estate | F34: 1
B35: Administrative / Business Operations | F35: 1
B36: Other | F36: 1
B37: TOTAL | C37: =SUM(C33:C36)
B38: If Other, what does that time consist of? | F38: 1
A40: 3. WHERE DOES YOUR TIME ACTUALLY GO?
A41: You do not need to track every minute. Think about a typical week and make your best estimate. Use this guide if you are unsure how to categorize something.
B42: Category | C42: Examples
B43: Prospecting / Business Development | C43: Cold calling, owner outreach, tenant outreach, email campaigns, canvassing, prospect research
B44: Client / Deal Work | C44: Tours, client meetings, LOIs, contracts, negotiations, due diligence, inspections, closing coordination
B45: Market Research | C45: Crexi, CoStar, GIS, Land id, researching ownership, comps, zoning, demographics
...

Sheet Agent 3 Scorecard
A1: =IF('Settings'!B16="","Agent 3",'Settings'!B16)&" — Weekly Score Card"
A2: Fill in your row for the current week by Friday end of day (yellow cells). Estimates are fine. “Follow-Ups Outstanding” and “Pipeline Potential GCI” are snapshots as of the end of the week; everything else is what happened that week. Q4 progress below updates automatically.
A4: Q4 2026 PROGRESS (goals come from Section 13 of your Assessment) | H4: ACCOUNTABILITY
A5: Metric | C5: Q4 Goal | D5: Q4 Actual | E5: % to Goal | F5: On Pace? | H5: Weeks updated | K5: =COUNTIFS($A$15:$A$80,"<="&TODAY(),$Y$15:$Y$80,"<>")
A6: Commercial GCI | C6: =IF('Agent 3 Assessment'!C285="","",'Agent 3 Assessment'!C285) | D6: =SUMIFS($T$15:$T$80,$A$15:$A$80,">="&DATE(2026,9,28),$A$15:$A$80,"<="&DATE(2026,12,31)) | E6: =IFERROR(D6/C6,"") | F6: =IF(C6="","Set goal",IF(D6>=C6*MAX(0,MIN(1,(TODAY()-DATE(2026,10,1))/(DATE(2026,12,31)-DATE(2026,10,1)))),"On pace","Behind")) | H6: Weeks elapsed | K6: =COUNTIFS($A$15:$A$80,"<="&TODAY())
A7: Transaction Volume | C7: =IF('Agent 3 Assessment'!C284="","",'Agent 3 Assessment'!C284) | D7: =SUMIFS($S$15:$S$80,$A$15:$A$80,">="&DATE(2026,9,28),$A$15:$A$80,"<="&DATE(2026,12,31)) | E7: =IFERROR(D7/C7,"") | F7: =IF(C7="","Set goal",IF(D7>=C7*MAX(0,MIN(1,(TODAY()-DATE(2026,10,1))/(DATE(2026,12,31)-DATE(2026,10,1)))),"On pace","Behind")) | H7: Consistency | K7: =IFERROR(K5/K6,0)
A8: Closings | C8: =IF('Agent 3 Assessment'!C286="","",'Agent 3 Assessment'!C286) | D8: =SUMIFS($R$15:$R$80,$A$15:$A$80,">="&DATE(2026,9,28),$A$15:$A$80,"<="&DATE(2026,12,31)) | E8: =IFERROR(D8/C8,"") | F8: =IF(C8="","Set goal",IF(D8>=C8*MAX(0,MIN(1,(TODAY()-DATE(2026,10,1))/(DATE(2026,12,31)-DATE(2026,10,1)))),"On pace","Behind")) | H8: Avg calls / week | K8: =IFERROR(AVERAGEIFS($F$15:$F$80,$A$15:$A$80,"<="&TODAY(),$F$15:$F$80,"<>"),0)
A9: New Listings | C9: =IF('Agent 3 Assessment'!C287="","",'Agent 3 Assessment'!C287) | D9: =SUMIFS($N$15:$N$80,$A$15:$A$80,">="&DATE(2026,9,28),$A$15:$A$80,"<="&DATE(2026,12,31)) | E9: =IFERROR(D9/C9,"") | F9: =IF(C9="","Set goal",IF(D9>=C9*MAX(0,MIN(1,(TODAY()-DATE(2026,10,1))/(DATE(2026,12,31)-DATE(2026,10,1)))),"On pace","Behind")) | H9: Avg meetings / week | K9: =IFERROR(AVERAGEIFS($H$15:$H$80,$A$15:$A$80,"<="&TODAY(),$H$15:$H$80,"<>"),0)
A10: New Buyer / Tenant Assignments | C10: =IF('Agent 3 Assessment'!C288="","",'Agent 3 Assessment'!C288) | D10: =SUMIFS($O$15:$O$80,$A$15:$A$80,">="&DATE(2026,9,28),$A$15:$A$80,"<="&DATE(2026,12,31)) | E10: =IFERROR(D10/C10,"") | F10: =IF(C10="","Set goal",IF(D10>=C10*MAX(0,MIN(1,(TODAY()-DATE(2026,10,1))/(DATE(2026,12,31)-DATE(2026,10,1)))),"On pace","Behind")) | H10: Latest pipeline GCI | K10: =IFERROR(INDEX($U$15:$U$80,MATCH(1E+100,$U$15:$U$80)),"")
A11: Qualified Opportunities Created | C11: =IF('Agent 3 Assessment'!C289="","",'Agent 3 Assessment'!C289) | D11: =SUMIFS($I$15:$I$80,$A$15:$A$80,">="&DATE(2026,9,28),$A$15:$A$80,"<="&DATE(2026,12,31)) | E11: =IFERROR(D11/C11,"") | F11: =IF(C11="","Set goal",IF(D11>=C11*MAX(0,MIN(1,(TODAY()-DATE(2026,10,1))/(DATE(2026,12,31)-DATE(2026,10,1)))),"On pace","Behind")) | H11: Assessment complete | K11: ='Agent 3 Assessment'!C3
A12: Meetings (goal = per month × 3) | C12: =IF('Agent 3 Assessment'!C290="","",'Agent 3 Assessment'!C290*3) | D12: =SUMIFS($H$15:$H$80,$A$15:$A$80,">="&DATE(2026,9,28),$A$15:$A$80,"<="&DATE(2026,12,31)) | E12: =IFERROR(D12/C12,"") | F12: =IF(C12="","Set goal",IF(D12>=C12*MAX(0,MIN(1,(TODAY()-DATE(2026,10,1))/(DATE(2026,12,31)-DATE(2026,10,1)))),"On pace","Behind"))
A14: Week Of (Mon) | B14: Days Worked | C14: Total RE Hours | D14: Commercial Hours | E14: Prospecting Hours | F14: Calls / Outreach Attempts | G14: Decision-Maker Conversations | H14: Prospect / Client Meetings | I14: New Opportunities Created | J14: New Database Contacts | K14: Follow-Ups Outstanding | L14: Market Center Agent Conversations | M14: Sphere Touches | N14: New Listings | O14: New Buyer / Tenant Assignments | P14: LOIs Submitted | Q14: Went Under Contract | R14: Closings | S14: Volume Closed ($) | T14: GCI Closed ($) | U14: Pipeline Potential GCI ($) | V14: Win of the Week | W14: Biggest Obstacle | X14: #1 Focus Next Week | Y14: Last Updated (auto) | Z14: Status
A15: 46293 | Z15: =IF(A15>TODAY(),"Upcoming",IF(Y15<>"","✓ Updated",IF(A15+6>=TODAY(),"Due Friday","⚠ Missing")))
A16: 46300 | Z16: =IF(A16>TODAY(),"Upcoming",IF(Y16<>"","✓ Updated",IF(A16+6>=TODAY(),"Due Friday","⚠ Missing")))
A17: 46307 | Z17: =IF(A17>TODAY(),"Upcoming",IF(Y17<>"","✓ Updated",IF(A17+6>=TODAY(),"Due Friday","⚠ Missing")))
A18: 46314 | Z18: =IF(A18>TODAY(),"Upcoming",IF(Y18<>"","✓ Updated",IF(A18+6>=TODAY(),"Due Friday","⚠ Missing")))
A19: 46321 | Z19: =IF(A19>TODAY(),"Upcoming",IF(Y19<>"","✓ Updated",IF(A19+6>=TODAY(),"Due Friday","⚠ Missing")))
A20: 46328 | Z20: =IF(A20>TODAY(),"Upcoming",IF(Y20<>"","✓ Updated",IF(A20+6>=TODAY(),"Due Friday","⚠ Missing")))
A21: 46335 | Z21: =IF(A21>TODAY(),"Upcoming",IF(Y21<>"","✓ Updated",IF(A21+6>=TODAY(),"Due Friday","⚠ Missing")))
A22: 46342 | Z22: =IF(A22>TODAY(),"Upcoming",IF(Y22<>"","✓ Updated",IF(A22+6>=TODAY(),"Due Friday","⚠ Missing")))
A23: 46349 | Z23: =IF(A23>TODAY(),"Upcoming",IF(Y23<>"","✓ Updated",IF(A23+6>=TODAY(),"Due Friday","⚠ Missing")))
A24: 46356 | Z24: =IF(A24>TODAY(),"Upcoming",IF(Y24<>"","✓ Updated",IF(A24+6>=TODAY(),"Due Friday","⚠ Missing")))
A25: 46363 | Z25: =IF(A25>TODAY(),"Upcoming",IF(Y25<>"","✓ Updated",IF(A25+6>=TODAY(),"Due Friday","⚠ Missing")))
A26: 46370 | Z26: =IF(A26>TODAY(),"Upcoming",IF(Y26<>"","✓ Updated",IF(A26+6>=TODAY(),"Due Friday","⚠ Missing")))
... A80: 46748 | Z80: =IF(A80>TODAY(),"Upcoming",IF(Y80<>"","✓ Updated",IF(A80+6>=TODAY(),"Due Friday","⚠ Missing")))

Sheet Agent 3 Assessment
A1: =IF('Settings'!B16="","Agent 3",'Settings'!B16)&" — Business Development & Growth Assessment"
A2: THE PRAEDIUM GROUP • This assessment helps us understand where you are today, where your time is going, and what training, structure, or support could help you grow. There are no “right” answers — answer based on what your business actually looks like today. Estimates are completely acceptable. Yellow cells are yours to fill in.
B3: Completion: | C3: =IFERROR(SUMPRODUCT((F5:F400=1)*(C5:C400<>""))/SUM(F5:F400),0)
A5: 1. ABOUT YOUR BUSINESS TODAY
B6: Market Center / KW Office | F6: 1
B7: How long have you been licensed in real estate? | F7: 1
B8: How long have you actively worked in commercial real estate? | F8: 1
B9: How would you describe your current real estate business? | F9: 1
B10: If you selected Other, please explain: | F10: 1
B11: Is real estate currently your primary occupation? | F11: 1
B12: If not, what other work or major commitments currently compete for your time? | F12: 1
A14: 2. YOUR CURRENT WORK WEEK
A15: We want to understand what your schedule actually looks like today.
B16: On average, how many days per week do you currently spend working on real estate? | F16: 1
B17: How many hours do you work on real estate during a typical day? | F17: 1
B18: What time do you normally begin your workday? | F18: 1
B19: What time do you normally finish your workday? | F19: 1
B20: Is your schedule generally consistent from day to day? | F20: 1
B22: Day | C22: Usually Work? | D22: Approx. Hours
B23: Monday | F23: 1
B24: Tuesday | F24: 1
B25: Wednesday | F25: 1
B26: Thursday | F26: 1
B27: Friday | F27: 1
B28: Saturday | F28: 1
B29: Sunday | F29: 1
B31: How is your typical real estate week divided?
B32: Area | C32: Hours / Week
B33: Commercial Real Estate | F33: 1
B34: Residential Real Estate | F34: 1
B35: Administrative / Business Operations | F35: 1
B36: Other | F36: 1
B37: TOTAL | C37: =SUM(C33:C36)
B38: If Other, what does that time consist of? | F38: 1
A40: 3. WHERE DOES YOUR TIME ACTUALLY GO?
A41: You do not need to track every minute. Think about a typical week and make your best estimate. Use this guide if you are unsure how to categorize something.
B42: Category | C42: Examples
B43: Prospecting / Business Development | C43: Cold calling, owner outreach, tenant outreach, email campaigns, canvassing, prospect research
B44: Client / Deal Work | C44: Tours, client meetings, LOIs, contracts, negotiations, due diligence, inspections, closing coordination
B45: Market Research | C45: Crexi, CoStar, GIS, Land id, researching ownership, comps, zoning, demographics
...

Sheet Agent 4 Scorecard
A1: =IF('Settings'!B17="","Agent 4",'Settings'!B17)&" — Weekly Score Card"
A2: Fill in your row for the current week by Friday end of day (yellow cells). Estimates are fine. “Follow-Ups Outstanding” and “Pipeline Potential GCI” are snapshots as of the end of the week; everything else is what happened that week. Q4 progress below updates automatically.
A4: Q4 2026 PROGRESS (goals come from Section 13 of your Assessment) | H4: ACCOUNTABILITY
A5: Metric | C5: Q4 Goal | D5: Q4 Actual | E5: % to Goal | F5: On Pace? | H5: Weeks updated | K5: =COUNTIFS($A$15:$A$80,"<="&TODAY(),$Y$15:$Y$80,"<>")
A6: Commercial GCI | C6: =IF('Agent 4 Assessment'!C285="","",'Agent 4 Assessment'!C285) | D6: =SUMIFS($T$15:$T$80,$A$15:$A$80,">="&DATE(2026,9,28),$A$15:$A$80,"<="&DATE(2026,12,31)) | E6: =IFERROR(D6/C6,"") | F6: =IF(C6="","Set goal",IF(D6>=C6*MAX(0,MIN(1,(TODAY()-DATE(2026,10,1))/(DATE(2026,12,31)-DATE(2026,10,1)))),"On pace","Behind")) | H6: Weeks elapsed | K6: =COUNTIFS($A$15:$A$80,"<="&TODAY())
A7: Transaction Volume | C7: =IF('Agent 4 Assessment'!C284="","",'Agent 4 Assessment'!C284) | D7: =SUMIFS($S$15:$S$80,$A$15:$A$80,">="&DATE(2026,9,28),$A$15:$A$80,"<="&DATE(2026,12,31)) | E7: =IFERROR(D7/C7,"") | F7: =IF(C7="","Set goal",IF(D7>=C7*MAX(0,MIN(1,(TODAY()-DATE(2026,10,1))/(DATE(2026,12,31)-DATE(2026,10,1)))),"On pace","Behind")) | H7: Consistency | K7: =IFERROR(K5/K6,0)
A8: Closings | C8: =IF('Agent 4 Assessment'!C286="","",'Agent 4 Assessment'!C286) | D8: =SUMIFS($R$15:$R$80,$A$15:$A$80,">="&DATE(2026,9,28),$A$15:$A$80,"<="&DATE(2026,12,31)) | E8: =IFERROR(D8/C8,"") | F8: =IF(C8="","Set goal",IF(D8>=C8*MAX(0,MIN(1,(TODAY()-DATE(2026,10,1))/(DATE(2026,12,31)-DATE(2026,10,1)))),"On pace","Behind")) | H8: Avg calls / week | K8: =IFERROR(AVERAGEIFS($F$15:$F$80,$A$15:$A$80,"<="&TODAY(),$F$15:$F$80,"<>"),0)
A9: New Listings | C9: =IF('Agent 4 Assessment'!C287="","",'Agent 4 Assessment'!C287) | D9: =SUMIFS($N$15:$N$80,$A$15:$A$80,">="&DATE(2026,9,28),$A$15:$A$80,"<="&DATE(2026,12,31)) | E9: =IFERROR(D9/C9,"") | F9: =IF(C9="","Set goal",IF(D9>=C9*MAX(0,MIN(1,(TODAY()-DATE(2026,10,1))/(DATE(2026,12,31)-DATE(2026,10,1)))),"On pace","Behind")) | H9: Avg meetings / week | K9: =IFERROR(AVERAGEIFS($H$15:$H$80,$A$15:$A$80,"<="&TODAY(),$H$15:$H$80,"<>"),0)
A10: New Buyer / Tenant Assignments | C10: =IF('Agent 4 Assessment'!C288="","",'Agent 4 Assessment'!C288) | D10: =SUMIFS($O$15:$O$80,$A$15:$A$80,">="&DATE(2026,9,28),$A$15:$A$80,"<="&DATE(2026,12,31)) | E10: =IFERROR(D10/C10,"") | F10: =IF(C10="","Set goal",IF(D10>=C10*MAX(0,MIN(1,(TODAY()-DATE(2026,10,1))/(DATE(2026,12,31)-DATE(2026,10,1)))),"On pace","Behind")) | H10: Latest pipeline GCI | K10: =IFERROR(INDEX($U$15:$U$80,MATCH(1E+100,$U$15:$U$80)),"")
A11: Qualified Opportunities Created | C11: =IF('Agent 4 Assessment'!C289="","",'Agent 4 Assessment'!C289) | D11: =SUMIFS($I$15:$I$80,$A$15:$A$80,">="&DATE(2026,9,28),$A$15:$A$80,"<="&DATE(2026,12,31)) | E11: =IFERROR(D11/C11,"") | F11: =IF(C11="","Set goal",IF(D11>=C11*MAX(0,MIN(1,(TODAY()-DATE(2026,10,1))/(DATE(2026,12,31)-DATE(2026,10,1)))),"On pace","Behind")) | H11: Assessment complete | K11: ='Agent 4 Assessment'!C3
A12: Meetings (goal = per month × 3) | C12: =IF('Agent 4 Assessment'!C290="","",'Agent 4 Assessment'!C290*3) | D12: =SUMIFS($H$15:$H$80,$A$15:$A$80,">="&DATE(2026,9,28),$A$15:$A$80,"<="&DATE(2026,12,31)) | E12: =IFERROR(D12/C12,"") | F12: =IF(C12="","Set goal",IF(D12>=C12*MAX(0,MIN(1,(TODAY()-DATE(2026,10,1))/(DATE(2026,12,31)-DATE(2026,10,1)))),"On pace","Behind"))
A14: Week Of (Mon) | B14: Days Worked | C14: Total RE Hours | D14: Commercial Hours | E14: Prospecting Hours | F14: Calls / Outreach Attempts | G14: Decision-Maker Conversations | H14: Prospect / Client Meetings | I14: New Opportunities Created | J14: New Database Contacts | K14: Follow-Ups Outstanding | L14: Market Center Agent Conversations | M14: Sphere Touches | N14: New Listings | O14: New Buyer / Tenant Assignments | P14: LOIs Submitted | Q14: Went Under Contract | R14: Closings | S14: Volume Closed ($) | T14: GCI Closed ($) | U14: Pipeline Potential GCI ($) | V14: Win of the Week | W14: Biggest Obstacle | X14: #1 Focus Next Week | Y14: Last Updated (auto) | Z14: Status
A15: 46293 | Z15: =IF(A15>TODAY(),"Upcoming",IF(Y15<>"","✓ Updated",IF(A15+6>=TODAY(),"Due Friday","⚠ Missing")))
A16: 46300 | Z16: =IF(A16>TODAY(),"Upcoming",IF(Y16<>"","✓ Updated",IF(A16+6>=TODAY(),"Due Friday","⚠ Missing")))
A17: 46307 | Z17: =IF(A17>TODAY(),"Upcoming",IF(Y17<>"","✓ Updated",IF(A17+6>=TODAY(),"Due Friday","⚠ Missing")))
A18: 46314 | Z18: =IF(A18>TODAY(),"Upcoming",IF(Y18<>"","✓ Updated",IF(A18+6>=TODAY(),"Due Friday","⚠ Missing")))
A19: 46321 | Z19: =IF(A19>TODAY(),"Upcoming",IF(Y19<>"","✓ Updated",IF(A19+6>=TODAY(),"Due Friday","⚠ Missing")))
A20: 46328 | Z20: =IF(A20>TODAY(),"Upcoming",IF(Y20<>"","✓ Updated",IF(A20+6>=TODAY(),"Due Friday","⚠ Missing")))
A21: 46335 | Z21: =IF(A21>TODAY(),"Upcoming",IF(Y21<>"","✓ Updated",IF(A21+6>=TODAY(),"Due Friday","⚠ Missing")))
A22: 46342 | Z22: =IF(A22>TODAY(),"Upcoming",IF(Y22<>"","✓ Updated",IF(A22+6>=TODAY(),"Due Friday","⚠ Missing")))
A23: 46349 | Z23: =IF(A23>TODAY(),"Upcoming",IF(Y23<>"","✓ Updated",IF(A23+6>=TODAY(),"Due Friday","⚠ Missing")))
A24: 46356 | Z24: =IF(A24>TODAY(),"Upcoming",IF(Y24<>"","✓ Updated",IF(A24+6>=TODAY(),"Due Friday","⚠ Missing")))
A25: 46363 | Z25: =IF(A25>TODAY(),"Upcoming",IF(Y25<>"","✓ Updated",IF(A25+6>=TODAY(),"Due Friday","⚠ Missing")))
A26: 46370 | Z26: =IF(A26>TODAY(),"Upcoming",IF(Y26<>"","✓ Updated",IF(A26+6>=TODAY(),"Due Friday","⚠ Missing")))
... A80: 46748 | Z80: =IF(A80>TODAY(),"Upcoming",IF(Y80<>"","✓ Updated",IF(A80+6>=TODAY(),"Due Friday","⚠ Missing")))

Sheet Agent 4 Assessment
A1: =IF('Settings'!B17="","Agent 4",'Settings'!B17)&" — Business Development & Growth Assessment"
A2: THE PRAEDIUM GROUP • This assessment helps us understand where you are today, where your time is going, and what training, structure, or support could help you grow. There are no “right” answers — answer based on what your business actually looks like today. Estimates are completely acceptable. Yellow cells are yours to fill in.
B3: Completion: | C3: =IFERROR(SUMPRODUCT((F5:F400=1)*(C5:C400<>""))/SUM(F5:F400),0)
A5: 1. ABOUT YOUR BUSINESS TODAY
B6: Market Center / KW Office | F6: 1
B7: How long have you been licensed in real estate? | F7: 1
B8: How long have you actively worked in commercial real estate? | F8: 1
B9: How would you describe your current real estate business? | F9: 1
B10: If you selected Other, please explain: | F10: 1
B11: Is real estate currently your primary occupation? | F11: 1
B12: If not, what other work or major commitments currently compete for your time? | F12: 1
A14: 2. YOUR CURRENT WORK WEEK
A15: We want to understand what your schedule actually looks like today.
B16: On average, how many days per week do you currently spend working on real estate? | F16: 1
B17: How many hours do you work on real estate during a typical day? | F17: 1
B18: What time do you normally begin your workday? | F18: 1
B19: What time do you normally finish your workday? | F19: 1
B20: Is your schedule generally consistent from day to day? | F20: 1
B22: Day | C22: Usually Work? | D22: Approx. Hours
B23: Monday | F23: 1
B24: Tuesday | F24: 1
B25: Wednesday | F25: 1
B26: Thursday | F26: 1
B27: Friday | F27: 1
B28: Saturday | F28: 1
B29: Sunday | F29: 1
B31: How is your typical real estate week divided?
B32: Area | C32: Hours / Week
B33: Commercial Real Estate | F33: 1
B34: Residential Real Estate | F34: 1
B35: Administrative / Business Operations | F35: 1
B36: Other | F36: 1
B37: TOTAL | C37: =SUM(C33:C36)
B38: If Other, what does that time consist of? | F38: 1
A40: 3. WHERE DOES YOUR TIME ACTUALLY GO?
A41: You do not need to track every minute. Think about a typical week and make your best estimate. Use this guide if you are unsure how to categorize something.
B42: Category | C42: Examples
B43: Prospecting / Business Development | C43: Cold calling, owner outreach, tenant outreach, email campaigns, canvassing, prospect research
B44: Client / Deal Work | C44: Tours, client meetings, LOIs, contracts, negotiations, due diligence, inspections, closing coordination
B45: Market Research | C45: Crexi, CoStar, GIS, Land id, researching ownership, comps, zoning, demographics
...

Sheet Agent 5 Scorecard
A1: =IF('Settings'!B18="","Agent 5",'Settings'!B18)&" — Weekly Score Card"
A2: Fill in your row for the current week by Friday end of day (yellow cells). Estimates are fine. “Follow-Ups Outstanding” and “Pipeline Potential GCI” are snapshots as of the end of the week; everything else is what happened that week. Q4 progress below updates automatically.
A4: Q4 2026 PROGRESS (goals come from Section 13 of your Assessment) | H4: ACCOUNTABILITY
A5: Metric | C5: Q4 Goal | D5: Q4 Actual | E5: % to Goal | F5: On Pace? | H5: Weeks updated | K5: =COUNTIFS($A$15:$A$80,"<="&TODAY(),$Y$15:$Y$80,"<>")
A6: Commercial GCI | C6: =IF('Agent 5 Assessment'!C285="","",'Agent 5 Assessment'!C285) | D6: =SUMIFS($T$15:$T$80,$A$15:$A$80,">="&DATE(2026,9,28),$A$15:$A$80,"<="&DATE(2026,12,31)) | E6: =IFERROR(D6/C6,"") | F6: =IF(C6="","Set goal",IF(D6>=C6*MAX(0,MIN(1,(TODAY()-DATE(2026,10,1))/(DATE(2026,12,31)-DATE(2026,10,1)))),"On pace","Behind")) | H6: Weeks elapsed | K6: =COUNTIFS($A$15:$A$80,"<="&TODAY())
A7: Transaction Volume | C7: =IF('Agent 5 Assessment'!C284="","",'Agent 5 Assessment'!C284) | D7: =SUMIFS($S$15:$S$80,$A$15:$A$80,">="&DATE(2026,9,28),$A$15:$A$80,"<="&DATE(2026,12,31)) | E7: =IFERROR(D7/C7,"") | F7: =IF(C7="","Set goal",IF(D7>=C7*MAX(0,MIN(1,(TODAY()-DATE(2026,10,1))/(DATE(2026,12,31)-DATE(2026,10,1)))),"On pace","Behind")) | H7: Consistency | K7: =IFERROR(K5/K6,0)
A8: Closings | C8: =IF('Agent 5 Assessment'!C286="","",'Agent 5 Assessment'!C286) | D8: =SUMIFS($R$15:$R$80,$A$15:$A$80,">="&DATE(2026,9,28),$A$15:$A$80,"<="&DATE(2026,12,31)) | E8: =IFERROR(D8/C8,"") | F8: =IF(C8="","Set goal",IF(D8>=C8*MAX(0,MIN(1,(TODAY()-DATE(2026,10,1))/(DATE(2026,12,31)-DATE(2026,10,1)))),"On pace","Behind")) | H8: Avg calls / week | K8: =IFERROR(AVERAGEIFS($F$15:$F$80,$A$15:$A$80,"<="&TODAY(),$F$15:$F$80,"<>"),0)
A9: New Listings | C9: =IF('Agent 5 Assessment'!C287="","",'Agent 5 Assessment'!C287) | D9: =SUMIFS($N$15:$N$80,$A$15:$A$80,">="&DATE(2026,9,28),$A$15:$A$80,"<="&DATE(2026,12,31)) | E9: =IFERROR(D9/C9,"") | F9: =IF(C9="","Set goal",IF(D9>=C9*MAX(0,MIN(1,(TODAY()-DATE(2026,10,1))/(DATE(2026,12,31)-DATE(2026,10,1)))),"On pace","Behind")) | H9: Avg meetings / week | K9: =IFERROR(AVERAGEIFS($H$15:$H$80,$A$15:$A$80,"<="&TODAY(),$H$15:$H$80,"<>"),0)
A10: New Buyer / Tenant Assignments | C10: =IF('Agent 5 Assessment'!C288="","",'Agent 5 Assessment'!C288) | D10: =SUMIFS($O$15:$O$80,$A$15:$A$80,">="&DATE(2026,9,28),$A$15:$A$80,"<="&DATE(2026,12,31)) | E10: =IFERROR(D10/C10,"") | F10: =IF(C10="","Set goal",IF(D10>=C10*MAX(0,MIN(1,(TODAY()-DATE(2026,10,1))/(DATE(2026,12,31)-DATE(2026,10,1)))),"On pace","Behind")) | H10: Latest pipeline GCI | K10: =IFERROR(INDEX($U$15:$U$80,MATCH(1E+100,$U$15:$U$80)),"")
A11: Qualified Opportunities Created | C11: =IF('Agent 5 Assessment'!C289="","",'Agent 5 Assessment'!C289) | D11: =SUMIFS($I$15:$I$80,$A$15:$A$80,">="&DATE(2026,9,28),$A$15:$A$80,"<="&DATE(2026,12,31)) | E11: =IFERROR(D11/C11,"") | F11: =IF(C11="","Set goal",IF(D11>=C11*MAX(0,MIN(1,(TODAY()-DATE(2026,10,1))/(DATE(2026,12,31)-DATE(2026,10,1)))),"On pace","Behind")) | H11: Assessment complete | K11: ='Agent 5 Assessment'!C3
A12: Meetings (goal = per month × 3) | C12: =IF('Agent 5 Assessment'!C290="","",'Agent 5 Assessment'!C290*3) | D12: =SUMIFS($H$15:$H$80,$A$15:$A$80,">="&DATE(2026,9,28),$A$15:$A$80,"<="&DATE(2026,12,31)) | E12: =IFERROR(D12/C12,"") | F12: =IF(C12="","Set goal",IF(D12>=C12*MAX(0,MIN(1,(TODAY()-DATE(2026,10,1))/(DATE(2026,12,31)-DATE(2026,10,1)))),"On pace","Behind"))
A14: Week Of (Mon) | B14: Days Worked | C14: Total RE Hours | D14: Commercial Hours | E14: Prospecting Hours | F14: Calls / Outreach Attempts | G14: Decision-Maker Conversations | H14: Prospect / Client Meetings | I14: New Opportunities Created | J14: New Database Contacts | K14: Follow-Ups Outstanding | L14: Market Center Agent Conversations | M14: Sphere Touches | N14: New Listings | O14: New Buyer / Tenant Assignments | P14: LOIs Submitted | Q14: Went Under Contract | R14: Closings | S14: Volume Closed ($) | T14: GCI Closed ($) | U14: Pipeline Potential GCI ($) | V14: Win of the Week | W14: Biggest Obstacle | X14: #1 Focus Next Week | Y14: Last Updated (auto) | Z14: Status
A15: 46293 | Z15: =IF(A15>TODAY(),"Upcoming",IF(Y15<>"","✓ Updated",IF(A15+6>=TODAY(),"Due Friday","⚠ Missing")))
A16: 46300 | Z16: =IF(A16>TODAY(),"Upcoming",IF(Y16<>"","✓ Updated",IF(A16+6>=TODAY(),"Due Friday","⚠ Missing")))
A17: 46307 | Z17: =IF(A17>TODAY(),"Upcoming",IF(Y17<>"","✓ Updated",IF(A17+6>=TODAY(),"Due Friday","⚠ Missing")))
A18: 46314 | Z18: =IF(A18>TODAY(),"Upcoming",IF(Y18<>"","✓ Updated",IF(A18+6>=TODAY(),"Due Friday","⚠ Missing")))
A19: 46321 | Z19: =IF(A19>TODAY(),"Upcoming",IF(Y19<>"","✓ Updated",IF(A19+6>=TODAY(),"Due Friday","⚠ Missing")))
A20: 46328 | Z20: =IF(A20>TODAY(),"Upcoming",IF(Y20<>"","✓ Updated",IF(A20+6>=TODAY(),"Due Friday","⚠ Missing")))
A21: 46335 | Z21: =IF(A21>TODAY(),"Upcoming",IF(Y21<>"","✓ Updated",IF(A21+6>=TODAY(),"Due Friday","⚠ Missing")))
A22: 46342 | Z22: =IF(A22>TODAY(),"Upcoming",IF(Y22<>"","✓ Updated",IF(A22+6>=TODAY(),"Due Friday","⚠ Missing")))
A23: 46349 | Z23: =IF(A23>TODAY(),"Upcoming",IF(Y23<>"","✓ Updated",IF(A23+6>=TODAY(),"Due Friday","⚠ Missing")))
A24: 46356 | Z24: =IF(A24>TODAY(),"Upcoming",IF(Y24<>"","✓ Updated",IF(A24+6>=TODAY(),"Due Friday","⚠ Missing")))
A25: 46363 | Z25: =IF(A25>TODAY(),"Upcoming",IF(Y25<>"","✓ Updated",IF(A25+6>=TODAY(),"Due Friday","⚠ Missing")))
A26: 46370 | Z26: =IF(A26>TODAY(),"Upcoming",IF(Y26<>"","✓ Updated",IF(A26+6>=TODAY(),"Due Friday","⚠ Missing")))
... A80: 46748 | Z80: =IF(A80>TODAY(),"Upcoming",IF(Y80<>"","✓ Updated",IF(A80+6>=TODAY(),"Due Friday","⚠ Missing")))

Sheet Agent 5 Assessment
A1: =IF('Settings'!B18="","Agent 5",'Settings'!B18)&" — Business Development & Growth Assessment"
A2: THE PRAEDIUM GROUP • This assessment helps us understand where you are today, where your time is going, and what training, structure, or support could help you grow. There are no “right” answers — answer based on what your business actually looks like today. Estimates are completely acceptable. Yellow cells are yours to fill in.
B3: Completion: | C3: =IFERROR(SUMPRODUCT((F5:F400=1)*(C5:C400<>""))/SUM(F5:F400),0)
A5: 1. ABOUT YOUR BUSINESS TODAY
B6: Market Center / KW Office | F6: 1
B7: How long have you been licensed in real estate? | F7: 1
B8: How long have you actively worked in commercial real estate? | F8: 1
B9: How would you describe your current real estate business? | F9: 1
B10: If you selected Other, please explain: | F10: 1
B11: Is real estate currently your primary occupation? | F11: 1
B12: If not, what other work or major commitments currently compete for your time? | F12: 1
A14: 2. YOUR CURRENT WORK WEEK
A15: We want to understand what your schedule actually looks like today.
B16: On average, how many days per week do you currently spend working on real estate? | F16: 1
B17: How many hours do you work on real estate during a typical day? | F17: 1
B18: What time do you normally begin your workday? | F18: 1
B19: What time do you normally finish your workday? | F19: 1
B20: Is your schedule generally consistent from day to day? | F20: 1
B22: Day | C22: Usually Work? | D22: Approx. Hours
B23: Monday | F23: 1
B24: Tuesday | F24: 1
B25: Wednesday | F25: 1
B26: Thursday | F26: 1
B27: Friday | F27: 1
B28: Saturday | F28: 1
B29: Sunday | F29: 1
B31: How is your typical real estate week divided?
B32: Area | C32: Hours / Week
B33: Commercial Real Estate | F33: 1
B34: Residential Real Estate | F34: 1
B35: Administrative / Business Operations | F35: 1
B36: Other | F36: 1
B37: TOTAL | C37: =SUM(C33:C36)
B38: If Other, what does that time consist of? | F38: 1
A40: 3. WHERE DOES YOUR TIME ACTUALLY GO?
A41: You do not need to track every minute. Think about a typical week and make your best estimate. Use this guide if you are unsure how to categorize something.
B42: Category | C42: Examples
B43: Prospecting / Business Development | C43: Cold calling, owner outreach, tenant outreach, email campaigns, canvassing, prospect research
B44: Client / Deal Work | C44: Tours, client meetings, LOIs, contracts, negotiations, due diligence, inspections, closing coordination
B45: Market Research | C45: Crexi, CoStar, GIS, Land id, researching ownership, comps, zoning, demographics
...

Sheet Agent 6 Scorecard
A1: =IF('Settings'!B19="","Agent 6",'Settings'!B19)&" — Weekly Score Card"
A2: Fill in your row for the current week by Friday end of day (yellow cells). Estimates are fine. “Follow-Ups Outstanding” and “Pipeline Potential GCI” are snapshots as of the end of the week; everything else is what happened that week. Q4 progress below updates automatically.
A4: Q4 2026 PROGRESS (goals come from Section 13 of your Assessment) | H4: ACCOUNTABILITY
A5: Metric | C5: Q4 Goal | D5: Q4 Actual | E5: % to Goal | F5: On Pace? | H5: Weeks updated | K5: =COUNTIFS($A$15:$A$80,"<="&TODAY(),$Y$15:$Y$80,"<>")
A6: Commercial GCI | C6: =IF('Agent 6 Assessment'!C285="","",'Agent 6 Assessment'!C285) | D6: =SUMIFS($T$15:$T$80,$A$15:$A$80,">="&DATE(2026,9,28),$A$15:$A$80,"<="&DATE(2026,12,31)) | E6: =IFERROR(D6/C6,"") | F6: =IF(C6="","Set goal",IF(D6>=C6*MAX(0,MIN(1,(TODAY()-DATE(2026,10,1))/(DATE(2026,12,31)-DATE(2026,10,1)))),"On pace","Behind")) | H6: Weeks elapsed | K6: =COUNTIFS($A$15:$A$80,"<="&TODAY())
A7: Transaction Volume | C7: =IF('Agent 6 Assessment'!C284="","",'Agent 6 Assessment'!C284) | D7: =SUMIFS($S$15:$S$80,$A$15:$A$80,">="&DATE(2026,9,28),$A$15:$A$80,"<="&DATE(2026,12,31)) | E7: =IFERROR(D7/C7,"") | F7: =IF(C7="","Set goal",IF(D7>=C7*MAX(0,MIN(1,(TODAY()-DATE(2026,10,1))/(DATE(2026,12,31)-DATE(2026,10,1)))),"On pace","Behind")) | H7: Consistency | K7: =IFERROR(K5/K6,0)
A8: Closings | C8: =IF('Agent 6 Assessment'!C286="","",'Agent 6 Assessment'!C286) | D8: =SUMIFS($R$15:$R$80,$A$15:$A$80,">="&DATE(2026,9,28),$A$15:$A$80,"<="&DATE(2026,12,31)) | E8: =IFERROR(D8/C8,"") | F8: =IF(C8="","Set goal",IF(D8>=C8*MAX(0,MIN(1,(TODAY()-DATE(2026,10,1))/(DATE(2026,12,31)-DATE(2026,10,1)))),"On pace","Behind")) | H8: Avg calls / week | K8: =IFERROR(AVERAGEIFS($F$15:$F$80,$A$15:$A$80,"<="&TODAY(),$F$15:$F$80,"<>"),0)
A9: New Listings | C9: =IF('Agent 6 Assessment'!C287="","",'Agent 6 Assessment'!C287) | D9: =SUMIFS($N$15:$N$80,$A$15:$A$80,">="&DATE(2026,9,28),$A$15:$A$80,"<="&DATE(2026,12,31)) | E9: =IFERROR(D9/C9,"") | F9: =IF(C9="","Set goal",IF(D9>=C9*MAX(0,MIN(1,(TODAY()-DATE(2026,10,1))/(DATE(2026,12,31)-DATE(2026,10,1)))),"On pace","Behind")) | H9: Avg meetings / week | K9: =IFERROR(AVERAGEIFS($H$15:$H$80,$A$15:$A$80,"<="&TODAY(),$H$15:$H$80,"<>"),0)
